Workbook

Sheet Model
B1: Lufthansa Group – FY fuel price sensitivity after hedging
B2: Blue = input you can change · black = formula · green = link to Calibration sheet · yellow = key levers
B4: Global parameters (calibrated on 8 published grids, 2024–26)
B5: Barrels per tonne of jet fuel (k) | C5: 7.88
B6: Crack weight vs Brent (w) | C6: 1.15
B7: Strike dispersion σ ($/t) | C7: 181
B9: Scenario inputs | J9: Base FY price build-up: realised to date + remaining at base forwards
B10: Base Brent, months not yet realised ($/bbl) | C10: 84 | J10: H1 reported fuel expense incl. SAF (€m) | K10: 4176
B11: Base jet crack ($/bbl) | C11: 64 | J11: H1 mandatory SAF (€m) | K11: 90
B12: Base FY post-hedge jet price P0 ($/t) – calculated | C12: =($K$20+$K$15*$K$21+$K$22*$K$23)/$C$18 -> 1036.2086 | J12: H1 average USD/EUR | K12: 1.1664
B13: Months of the year not yet realised | C13: 5 | J13: H1 volume (mt) | K13: 4.4
B14: Share of FY volume still to price (s) | C14: =$K$22/$C$18 -> 0.43807502 | J14: Q3 volume (mt) | K14: 2.68
B15: Hedge ratio on remaining volume (h) | C15: 0.81 | J15: July volume (mt) | K15: =K14/3 -> 0.89333333
B16: Call-spread lower strike K1 ($/t jet) | C16: =Calibration!$C$6 -> 691 | J16: July Brent ($/bbl) | K16: 79.8
B17: Call-spread upper strike K2 ($/t jet) | C17: =Calibration!$D$6 -> 1299 | J17: July jet crack ($/bbl) | K17: 75.6
B18: FY jet fuel volume (mt) | C18: 9.42 | J18: July hedge ratio | K18: 0.82
B19: USD/EUR | C19: 1.151 | J19: Level offset A ($/t) | K19: 155
B20: Scenario Brent ($/bbl) | C20: 94 | J20: H1 realised fossil cost ($m) | K20: =(K10-K11)*K12 -> 4765.9104
B21: Scenario jet crack ($/bbl) | C21: 64 | J21: July post-hedge price ($/t) | K21: =((Model!$C$5*((K16)+Model!$C$6*(K17)))+$K$19-(K18)*((((Model!$C$5*((K16)+Model!$C$6*(K17)))-($C$16))*NORMSDIST(((Model!$C$5*((K16)+Model!$C$6*(K17)))-($C$16))/Model!$C$7)+Model!$C$7*EXP(-((((Model!$C$5*((K16)+Model!$C$6*(K17)))-($C$16))/Model!$C$7)^2)/2)/SQRT(2*PI()))-(((Model!$C$5*((K16)+Model!$C$6*(K17)))-($C$17))*NORMSDIST(((Model!$C$5*((K16)+Model!$C$6*(K17)))-($C$17))/Model!$C$7)+Model!$C$7*EXP(-((((Model!$C$5*((K16)+Model!$C$6*(K17)))-($C$17))/Model!$C$7)^2)/2)/SQRT(2*PI())))) -> 1023.6385
J22: Remaining volume Aug–Dec (mt) | K22: =$C$18-K13-K15 -> 4.1266667
B23: Outputs | J23: Remaining post-hedge price at base forwards ($/t) | K23: =((Model!$C$5*(($C$10)+Model!$C$6*($C$11)))+$K$19-($C$15)*((((Model!$C$5*(($C$10)+Model!$C$6*($C$11)))-($C$16))*NORMSDIST(((Model!$C$5*(($C$10)+Model!$C$6*($C$11)))-($C$16))/Model!$C$7)+Model!$C$7*EXP(-((((Model!$C$5*(($C$10)+Model!$C$6*($C$11)))-($C$16))/Model!$C$7)^2)/2)/SQRT(2*PI()))-(((Model!$C$5*(($C$10)+Model!$C$6*($C$11)))-($C$17))*NORMSDIST(((Model!$C$5*(($C$10)+Model!$C$6*($C$11)))-($C$17))/Model!$C$7)+Model!$C$7*EXP(-((((Model!$C$5*(($C$10)+Model!$C$6*($C$11)))-($C$17))/Model!$C$7)^2)/2)/SQRT(2*PI())))) -> 988.86704
B24: Market jet price at base, J0 ($/t) | C24: =Model!$C$5*(($C$10)+Model!$C$6*($C$11)) -> 1241.888 | J24: Calculated base FY price P0 ($/t) | K24: =$C$12 -> 1036.2086
B25: Market jet price in scenario, J ($/t) | C25: =Model!$C$5*(($C$20)+Model!$C$6*($C$21)) -> 1320.688 | J25: Lufthansa FY post-hedge price, 27 Jul 2026 ($/t) | K25: 1036
B26: Hedge protection at base ($/t hedged) | C26: =(((C24)-($C$16))*NORMSDIST(((C24)-($C$16))/Model!$C$7)+Model!$C$7*EXP(-((((C24)-($C$16))/Model!$C$7)^2)/2)/SQRT(2*PI()))-(((C24)-($C$17))*NORMSDIST(((C24)-($C$17))/Model!$C$7)+Model!$C$7*EXP(-((((C24)-($C$17))/Model!$C$7)^2)/2)/SQRT(2*PI())) -> 503.72958 | J26: Difference ($/t) | K26: =K24-K25 -> 0.20864524
B27: Hedge protection in scenario ($/t hedged) | C27: =(((C25)-($C$16))*NORMSDIST(((C25)-($C$16))/Model!$C$7)+Model!$C$7*EXP(-((((C25)-($C$16))/Model!$C$7)^2)/2)/SQRT(2*PI()))-(((C25)-($C$17))*NORMSDIST(((C25)-($C$17))/Model!$C$7)+Model!$C$7*EXP(-((((C25)-($C$17))/Model!$C$7)^2)/2)/SQRT(2*PI())) -> 546.1292 | J27: P0 = [H1 cost + July vol × July price + remaining vol × remaining price] ÷ FY volume
B28: Scenario FY post-hedge price P ($/t) | C28: =$C$12+$C$14*((C25-C24)-$C$15*(C27-C26)) -> 1055.6838 | J28: Remaining price = J0 + A − h·Prot(J0); July uses July prices and the July hedge ratio
B29: Base FY fossil fuel cost (€bn) | C29: =$C$18*$C$12/$C$19/1000 -> 8.480526
B30: Scenario FY fossil fuel cost (€bn) | C30: =$C$18*C28/$C$19/1000 -> 8.6399147
B31: Change vs base (€m) | C31: =(C30-C29)*1000 -> 159.38867
B32: Formula: P = P0 + s·[(J−J0) − h·(Prot(J) − Prot(J0))], J = k·(Brent + w·crack), Prot = smoothed call spread K1–K2
B34: Sensitivity grid: FY post-hedge price ($/t)
B35: Brent ↓ / crack → | C35: =$C$11+(-20) -> 44 | D35: =$C$11+(-10) -> 54 | E35: =$C$11+(0) -> 64 | F35: =$C$11+(10) -> 74 | G35: =$C$11+(20) -> 84
B36: =$C$10+(30) -> 114 | C36: =$C$12+$C$14*((Model!$C$5*(($B36)+Model!$C$6*(C$35)))-(Model!$C$5*(($C$10)+Model!$C$6*($C$11)))-$C$15*(((((Model!$C$5*(($B36)+Model!$C$6*(C$35)))-($C$16))*NORMSDIST(((Model!$C$5*(($B36)+Model!$C$6*(C$35)))-($C$16))/Model!$C$7)+Model!$C$7*EXP(-((((Model!$C$5*(($B36)+Model!$C$6*(C$35)))-($C$16))/Model!$C$7)^2)/2)/SQRT(2*PI()))-(((Model!$C$5*(($B36)+Model!$C$6*(C$35)))-($C$17))*NORMSDIST(((Model!$C$5*(($B36)+Model!$C$6*(C$35)))-($C$17))/Model!$C$7)+Model!$C$7*EXP(-((((Model!$C$5*(($B36)+Model!$C$6*(C$35)))-($C$17))/Model!$C$7)^2)/2)/SQRT(2*PI())))-((((Model!$C$5*(($C$10)+Model!$C$6*($C$11)))-($C$16))*NORMSDIST(((Model!$C$5*(($C$10)+Model!$C$6*($C$11)))-($C$16))/Model!$C$7)+Model!$C$7*EXP(-((((Model!$C$5*(($C$10)+Model!$C$6*($C$11)))-($C$16))/Model!$C$7)^2)/2)/SQRT(2*PI()))-(((Model!$C$5*(($C$10)+Model!$C$6*($C$11)))-($C$17))*NORMSDIST(((Model!$C$5*(($C$10)+Model!$C$6*($C$11)))-($C$17))/Model!$C$7)+Model!$C$7*EXP(-((((Model!$C$5*(($C$10)+Model!$C$6*($C$11)))-($C$17))/Model!$C$7)^2)/2)/SQRT(2*PI()))))) -> 1049.337 | D36: =$C$12+$C$14*((Model!$C$5*(($B36)+Model!$C$6*(D$35)))-(Model!$C$5*(($C$10)+Model!$C$6*($C$11)))-$C$15*(((((Model!$C$5*(($B36)+Model!$C$6*(D$35)))-($C$16))*NORMSDIST(((Model!$C$5*(($B36)+Model!$C$6*(D$35)))-($C$16))/Model!$C$7)+Model!$C$7*EXP(-((((Model!$C$5*(($B36)+Model!$C$6*(D$35)))-($C$16))/Model!$C$7)^2)/2)/SQRT(2*PI()))-(((Model!$C$5*(($B36)+Model!$C$6*(D$35)))-($C$17))*NORMSDIST(((Model!$C$5*(($B36)+Model!$C$6*(D$35)))-($C$17))/Model!$C$7)+Model!$C$7*EXP(-((((Model!$C$5*(($B36)+Model!$C$6*(D$35)))-($C$17))/Model!$C$7)^2)/2)/SQRT(2*PI())))-((((Model!$C$5*(($C$10)+Model!$C$6*($C$11)))-($C$16))*NORMSDIST(((Model!$C$5*(($C$10)+Model!$C$6*($C$11)))-($C$16))/Model!$C$7)+Model!$C$7*EXP(-((((Model!$C$5*(($C$10)+Model!$C$6*($C$11)))-($C$16))/Model!$C$7)^2)/2)/SQRT(2*PI()))-(((Model!$C$5*(($C$10)+Model!$C$6*($C$11)))-($C$17))*NORMSDIST(((Model!$C$5*(($C$10)+Model!$C$6*($C$11)))-($C$17))/Model!$C$7)+Model!$C$7*EXP(-((((Model!$C$5*(($C$10)+Model!$C$6*($C$11)))-($C$17))/Model!$C$7)^2)/2)/SQRT(2*PI()))))) -> 1075.9764 | E36: =$C$12+$C$14*((Model!$C$5*(($B36)+Model!$C$6*(E$35)))-(Model!$C$5*(($C$10)+Model!$C$6*($C$11)))-$C$15*(((((Model!$C$5*(($B36)+Model!$C$6*(E$35)))-($C$16))*NORMSDIST(((Model!$C$5*(($B36)+Model!$C$6*(E$35)))-($C$16))/Model!$C$7)+Model!$C$7*EXP(-((((Model!$C$5*(($B36)+Model!$C$6*(E$35)))-($C$16))/Model!$C$7)^2)/2)/SQRT(2*PI()))-(((Model!$C$5*(($B36)+Model!$C$6*(E$35)))-($C$17))*NORMSDIST(((Model!$C$5*(($B36)+Model!$C$6*(E$35)))-($C$17))/Model!$C$7)+Model!$C$7*EXP(-((((Model!$C$5*(($B36)+Model!$C$6*(E$35)))-($C$17))/Model!$C$7)^2)/2)/SQRT(2*PI())))-((((Model!$C$5*(($C$10)+Model!$C$6*($C$11)))-($C$16))*NORMSDIST(((Model!$C$5*(($C$10)+Model!$C$6*($C$11)))-($C$16))/Model!$C$7)+Model!$C$7*EXP(-((((Model!$C$5*(($C$10)+Model!$C$6*($C$11)))-($C$16))/Model!$C$7)^2)/2)/SQRT(2*PI()))-(((Model!$C$5*(($C$10)+Model!$C$6*($C$11)))-($C$17))*NORMSDIST(((Model!$C$5*(($C$10)+Model!$C$6*($C$11)))-($C$17))/Model!$C$7)+Model!$C$7*EXP(-((((Model!$C$5*(($C$10)+Model!$C$6*($C$11)))-($C$17))/Model!$C$7)^2)/2)/SQRT(2*PI()))))) -> 1108.2182 | F36: =$C$12+$C$14*((Model!$C$5*(($B36)+Model!$C$6*(F$35)))-(Model!$C$5*(($C$10)+Model!$C$6*($C$11)))-$C$15*(((((Model!$C$5*(($B36)+Model!$C$6*(F$35)))-($C$16))*NORMSDIST(((Model!$C$5*(($B36)+Model!$C$6*(F$35)))-($C$16))/Model!$C$7)+Model!$C$7*EXP(-((((Model!$C$5*(($B36)+Model!$C$6*(F$35)))-($C$16))/Model!$C$7)^2)/2)/SQRT(2*PI()))-(((Model!$C$5*(($B36)+Model!$C$6*(F$35)))-($C$17))*NORMSDIST(((Model!$C$5*(($B36)+Model!$C$6*(F$35)))-($C$17))/Model!$C$7)+Model!$C$7*EXP(-((((Model!$C$5*(($B36)+Model!$C$6*(F$35)))-($C$17))/Model!$C$7)^2)/2)/SQRT(2*PI())))-((((Model!$C$5*(($C$10)+Model!$C$6*($C$11)))-($C$16))*NORMSDIST(((Model!$C$5*(($C$10)+Model!$C$6*($C$11)))-($C$16))/Model!$C$7)+Model!$C$7*EXP(-((((Model!$C$5*(($C$10)+Model!$C$6*($C$11)))-($C$16))/Model!$C$7)^2)/2)/SQRT(2*PI()))-(((Model!$C$5*(($C$10)+Model!$C$6*($C$11)))-($C$17))*NORMSDIST(((Model!$C$5*(($C$10)+Model!$C$6*($C$11)))-($C$17))/Model!$C$7)+Model!$C$7*EXP(-((((Model!$C$5*(($C$10)+Model!$C$6*($C$11)))-($C$17))/Model!$C$7)^2)/2)/SQRT(2*PI()))))) -> 1144.3889 | G36: =$C$12+$C$14*((Model!$C$5*(($B36)+Model!$C$6*(G$35)))-(Model!$C$5*(($C$10)+Model!$C$6*($C$11)))-$C$15*(((((Model!$C$5*(($B36)+Model!$C$6*(G$35)))-($C$16))*NORMSDIST(((Model!$C$5*(($B36)+Model!$C$6*(G$35)))-($C$16))/Model!$C$7)+Model!$C$7*EXP(-((((Model!$C$5*(($B36)+Model!$C$6*(G$35)))-($C$16))/Model!$C$7)^2)/2)/SQRT(2*PI()))-(((Model!$C$5*(($B36)+Model!$C$6*(G$35)))-($C$17))*NORMSDIST(((Model!$C$5*(($B36)+Model!$C$6*(G$35)))-($C$17))/Model!$C$7)+Model!$C$7*EXP(-((((Model!$C$5*(($B36)+Model!$C$6*(G$35)))-($C$17))/Model!$C$7)^2)/2)/SQRT(2*PI())))-((((Model!$C$5*(($C$10)+Model!$C$6*($C$11)))-($C$16))*NORMSDIST(((Model!$C$5*(($C$10)+Model!$C$6*($C$11)))-($C$16))/Model!$C$7)+Model!$C$7*EXP(-((((Model!$C$5*(($C$10)+Model!$C$6*($C$11)))-($C$16))/Model!$C$7)^2)/2)/SQRT(2*PI()))-(((Model!$C$5*(($C$10)+Model!$C$6*($C$11)))-($C$17))*NORMSDIST(((Model!$C$5*(($C$10)+Model!$C$6*($C$11)))-($C$17))/Model!$C$7)+Model!$C$7*EXP(-((((Model!$C$5*(($C$10)+Model!$C$6*($C$11)))-($C$17))/Model!$C$7)^2)/2)/SQRT(2*PI()))))) -> 1182.7242
B37: =$C$10+(20) -> 104 | C37: =$C$12+$C$14*((Model!$C$5*(($B37)+Model!$C$6*(C$35)))-(Model!$C$5*(($C$10)+Model!$C$6*($C$11)))-$C$15*(((((Model!$C$5*(($B37)+Model!$C$6*(C$35)))-($C$16))*NORMSDIST(((Model!$C$5*(($B37)+Model!$C$6*(C$35)))-($C$16))/Model!$C$7)+Model!$C$7*EXP(-((((Model!$C$5*(($B37)+Model!$C$6*(C$35)))-($C$16))/Model!$C$7)^2)/2)/SQRT(2*PI()))-(((Model!$C$5*(($B37)+Model!$C$6*(C$35)))-($C$17))*NORMSDIST(((Model!$C$5*(($B37)+Model!$C$6*(C$35)))-($C$17))/Model!$C$7)+Model!$C$7*EXP(-((((Model!$C$5*(($B37)+Model!$C$6*(C$35)))-($C$17))/Model!$C$7)^2)/2)/SQRT(2*PI())))-((((Model!$C$5*(($C$10)+Model!$C$6*($C$11)))-($C$16))*NORMSDIST(((Model!$C$5*(($C$10)+Model!$C$6*($C$11)))-($C$16))/Model!$C$7)+Model!$C$7*EXP(-((((Model!$C$5*(($C$10)+Model!$C$6*($C$11)))-($C$16))/Model!$C$7)^2)/2)/SQRT(2*PI()))-(((Model!$C$5*(($C$10)+Model!$C$6*($C$11)))-($C$17))*NORMSDIST(((Model!$C$5*(($C$10)+Model!$C$6*($C$11)))-($C$17))/Model!$C$7)+Model!$C$7*EXP(-((((Model!$C$5*(($C$10)+Model!$C$6*($C$11)))-($C$17))/Model!$C$7)^2)/2)/SQRT(2*PI()))))) -> 1031.278 | D37: =$C$12+$C$14*((Model!$C$5*(($B37)+Model!$C$6*(D$35)))-(Model!$C$5*(($C$10)+Model!$C$6*($C$11)))-$C$15*(((((Model!$C$5*(($B37)+Model!$C$6*(D$35)))-($C$16))*NORMSDIST(((Model!$C$5*(($B37)+Model!$C$6*(D$35)))-($C$16))/Model!$C$7)+Model!$C$7*EXP(-((((Model!$C$5*(($B37)+Model!$C$6*(D$35)))-($C$16))/Model!$C$7)^2)/2)/SQRT(2*PI()))-(((Model!$C$5*(($B37)+Model!$C$6*(D$35)))-($C$17))*NORMSDIST(((Model!$C$5*(($B37)+Model!$C$6*(D$35)))-($C$17))/Model!$C$7)+Model!$C$7*EXP(-((((Model!$C$5*(($B37)+Model!$C$6*(D$35)))-($C$17))/Model!$C$7)^2)/2)/SQRT(2*PI())))-((((Model!$C$5*(($C$10)+Model!$C$6*($C$11)))-($C$16))*NORMSDIST(((Model!$C$5*(($C$10)+Model!$C$6*($C$11)))-($C$16))/Model!$C$7)+Model!$C$7*EXP(-((((Model!$C$5*(($C$10)+Model!$C$6*($C$11)))-($C$16))/Model!$C$7)^2)/2)/SQRT(2*PI()))-(((Model!$C$5*(($C$10)+Model!$C$6*($C$11)))-($C$17))*NORMSDIST(((Model!$C$5*(($C$10)+Model!$C$6*($C$11)))-($C$17))/Model!$C$7)+Model!$C$7*EXP(-((((Model!$C$5*(($C$10)+Model!$C$6*($C$11)))-($C$17))/Model!$C$7)^2)/2)/SQRT(2*PI()))))) -> 1052.4561 | E37: =$C$12+$C$14*((Model!$C$5*(($B37)+Model!$C$6*(E$35)))-(Model!$C$5*(($C$10)+Model!$C$6*($C$11)))-$C$15*(((((Model!$C$5*(($B37)+Model!$C$6*(E$35)))-($C$16))*NORMSDIST(((Model!$C$5*(($B37)+Model!$C$6*(E$35)))-($C$16))/Model!$C$7)+Model!$C$7*EXP(-((((Model!$C$5*(($B37)+Model!$C$6*(E$35)))-($C$16))/Model!$C$7)^2)/2)/SQRT(2*PI()))-(((Model!$C$5*(($B37)+Model!$C$6*(E$35)))-($C$17))*NORMSDIST(((Model!$C$5*(($B37)+Model!$C$6*(E$35)))-($C$17))/Model!$C$7)+Model!$C$7*EXP(-((((Model!$C$5*(($B37)+Model!$C$6*(E$35)))-($C$17))/Model!$C$7)^2)/2)/SQRT(2*PI())))-((((Model!$C$5*(($C$10)+Model!$C$6*($C$11)))-($C$16))*NORMSDIST(((Model!$C$5*(($C$10)+Model!$C$6*($C$11)))-($C$16))/Model!$C$7)+Model!$C$7*EXP(-((((Model!$C$5*(($C$10)+Model!$C$6*($C$11)))-($C$16))/Model!$C$7)^2)/2)/SQRT(2*PI()))-(((Model!$C$5*(($C$10)+Model!$C$6*($C$11)))-($C$17))*NORMSDIST(((Model!$C$5*(($C$10)+Model!$C$6*($C$11)))-($C$17))/Model!$C$7)+Model!$C$7*EXP(-((((Model!$C$5*(($C$10)+Model!$C$6*($C$11)))-($C$17))/Model!$C$7)^2)/2)/SQRT(2*PI()))))) -> 1079.8935 | F37: =$C$12+$C$14*((Model!$C$5*(($B37)+Model!$C$6*(F$35)))-(Model!$C$5*(($C$10)+Model!$C$6*($C$11)))-$C$15*(((((Model!$C$5*(($B37)+Model!$C$6*(F$35)))-($C$16))*NORMSDIST(((Model!$C$5*(($B37)+Model!$C$6*(F$35)))-($C$16))/Model!$C$7)+Model!$C$7*EXP(-((((Model!$C$5*(($B37)+Model!$C$6*(F$35)))-($C$16))/Model!$C$7)^2)/2)/SQRT(2*PI()))-(((Model!$C$5*(($B37)+Model!$C$6*(F$35)))-($C$17))*NORMSDIST(((Model!$C$5*(($B37)+Model!$C$6*(F$35)))-($C$17))/Model!$C$7)+Model!$C$7*EXP(-((((Model!$C$5*(($B37)+Model!$C$6*(F$35)))-($C$17))/Model!$C$7)^2)/2)/SQRT(2*PI())))-((((Model!$C$5*(($C$10)+Model!$C$6*($C$11)))-($C$16))*NORMSDIST(((Model!$C$5*(($C$10)+Model!$C$6*($C$11)))-($C$16))/Model!$C$7)+Model!$C$7*EXP(-((((Model!$C$5*(($C$10)+Model!$C$6*($C$11)))-($C$16))/Model!$C$7)^2)/2)/SQRT(2*PI()))-(((Model!$C$5*(($C$10)+Model!$C$6*($C$11)))-($C$17))*NORMSDIST(((Model!$C$5*(($C$10)+Model!$C$6*($C$11)))-($C$17))/Model!$C$7)+Model!$C$7*EXP(-((((Model!$C$5*(($C$10)+Model!$C$6*($C$11)))-($C$17))/Model!$C$7)^2)/2)/SQRT(2*PI()))))) -> 1112.7539 | G37: =$C$12+$C$14*((Model!$C$5*(($B37)+Model!$C$6*(G$35)))-(Model!$C$5*(($C$10)+Model!$C$6*($C$11)))-$C$15*(((((Model!$C$5*(($B37)+Model!$C$6*(G$35)))-($C$16))*NORMSDIST(((Model!$C$5*(($B37)+Model!$C$6*(G$35)))-($C$16))/Model!$C$7)+Model!$C$7*EXP(-((((Model!$C$5*(($B37)+Model!$C$6*(G$35)))-($C$16))/Model!$C$7)^2)/2)/SQRT(2*PI()))-(((Model!$C$5*(($B37)+Model!$C$6*(G$35)))-($C$17))*NORMSDIST(((Model!$C$5*(($B37)+Model!$C$6*(G$35)))-($C$17))/Model!$C$7)+Model!$C$7*EXP(-((((Model!$C$5*(($B37)+Model!$C$6*(G$35)))-($C$17))/Model!$C$7)^2)/2)/SQRT(2*PI())))-((((Model!$C$5*(($C$10)+Model!$C$6*($C$11)))-($C$16))*NORMSDIST(((Model!$C$5*(($C$10)+Model!$C$6*($C$11)))-($C$16))/Model!$C$7)+Model!$C$7*EXP(-((((Model!$C$5*(($C$10)+Model!$C$6*($C$11)))-($C$16))/Model!$C$7)^2)/2)/SQRT(2*PI()))-(((Model!$C$5*(($C$10)+Model!$C$6*($C$11)))-($C$17))*NORMSDIST(((Model!$C$5*(($C$10)+Model!$C$6*($C$11)))-($C$17))/Model!$C$7)+Model!$C$7*EXP(-((((Model!$C$5*(($C$10)+Model!$C$6*($C$11)))-($C$17))/Model!$C$7)^2)/2)/SQRT(2*PI()))))) -> 1149.2993
B38: =$C$10+(10) -> 94 | C38: =$C$12+$C$14*((Model!$C$5*(($B38)+Model!$C$6*(C$35)))-(Model!$C$5*(($C$10)+Model!$C$6*($C$11)))-$C$15*(((((Model!$C$5*(($B38)+Model!$C$6*(C$35)))-($C$16))*NORMSDIST(((Model!$C$5*(($B38)+Model!$C$6*(C$35)))-($C$16))/Model!$C$7)+Model!$C$7*EXP(-((((Model!$C$5*(($B38)+Model!$C$6*(C$35)))-($C$16))/Model!$C$7)^2)/2)/SQRT(2*PI()))-(((Model!$C$5*(($B38)+Model!$C$6*(C$35)))-($C$17))*NORMSDIST(((Model!$C$5*(($B38)+Model!$C$6*(C$35)))-($C$17))/Model!$C$7)+Model!$C$7*EXP(-((((Model!$C$5*(($B38)+Model!$C$6*(C$35)))-($C$17))/Model!$C$7)^2)/2)/SQRT(2*PI())))-((((Model!$C$5*(($C$10)+Model!$C$6*($C$11)))-($C$16))*NORMSDIST(((Model!$C$5*(($C$10)+Model!$C$6*($C$11)))-($C$16))/Model!$C$7)+Model!$C$7*EXP(-((((Model!$C$5*(($C$10)+Model!$C$6*($C$11)))-($C$16))/Model!$C$7)^2)/2)/SQRT(2*PI()))-(((Model!$C$5*(($C$10)+Model!$C$6*($C$11)))-($C$17))*NORMSDIST(((Model!$C$5*(($C$10)+Model!$C$6*($C$11)))-($C$17))/Model!$C$7)+Model!$C$7*EXP(-((((Model!$C$5*(($C$10)+Model!$C$6*($C$11)))-($C$17))/Model!$C$7)^2)/2)/SQRT(2*PI()))))) -> 1017.4824 | D38: =$C$12+$C$14*((Model!$C$5*(($B38)+Model!$C$6*(D$35)))-(Model!$C$5*(($C$10)+Model!$C$6*($C$11)))-$C$15*(((((Model!$C$5*(($B38)+Model!$C$6*(D$35)))-($C$16))*NORMSDIST(((Model!$C$5*(($B38)+Model!$C$6*(D$35)))-($C$16))/Model!$C$7)+Model!$C$7*EXP(-((((Model!$C$5*(($B38)+Model!$C$6*(D$35)))-($C$16))/Model!$C$7)^2)/2)/SQRT(2*PI()))-(((Model!$C$5*(($B38)+Model!$C$6*(D$35)))-($C$17))*NORMSDIST(((Model!$C$5*(($B38)+Model!$C$6*(D$35)))-($C$17))/Model!$C$7)+Model!$C$7*EXP(-((((Model!$C$5*(($B38)+Model!$C$6*(D$35)))-($C$17))/Model!$C$7)^2)/2)/SQRT(2*PI())))-((((Model!$C$5*(($C$10)+Model!$C$6*($C$11)))-($C$16))*NORMSDIST(((Model!$C$5*(($C$10)+Model!$C$6*($C$11)))-($C$16))/Model!$C$7)+Model!$C$7*EXP(-((((Model!$C$5*(($C$10)+Model!$C$6*($C$11)))-($C$16))/Model!$C$7)^2)/2)/SQRT(2*PI()))-(((Model!$C$5*(($C$10)+Model!$C$6*($C$11)))-($C$17))*NORMSDIST(((Model!$C$5*(($C$10)+Model!$C$6*($C$11)))-($C$17))/Model!$C$7)+Model!$C$7*EXP(-((((Model!$C$5*(($C$10)+Model!$C$6*($C$11)))-($C$17))/Model!$C$7)^2)/2)/SQRT(2*PI()))))) -> 1033.6932 | E38: =$C$12+$C$14*((Model!$C$5*(($B38)+Model!$C$6*(E$35)))-(Model!$C$5*(($C$10)+Model!$C$6*($C$11)))-$C$15*(((((Model!$C$5*(($B38)+Model!$C$6*(E$35)))-($C$16))*NORMSDIST(((Model!$C$5*(($B38)+Model!$C$6*(E$35)))-($C$16))/Model!$C$7)+Model!$C$7*EXP(-((((Model!$C$5*(($B38)+Model!$C$6*(E$35)))-($C$16))/Model!$C$7)^2)/2)/SQRT(2*PI()))-(((Model!$C$5*(($B38)+Model!$C$6*(E$35)))-($C$17))*NORMSDIST(((Model!$C$5*(($B38)+Model!$C$6*(E$35)))-($C$17))/Model!$C$7)+Model!$C$7*EXP(-((((Model!$C$5*(($B38)+Model!$C$6*(E$35)))-($C$17))/Model!$C$7)^2)/2)/SQRT(2*PI())))-((((Model!$C$5*(($C$10)+Model!$C$6*($C$11)))-($C$16))*NORMSDIST(((Model!$C$5*(($C$10)+Model!$C$6*($C$11)))-($C$16))/Model!$C$7)+Model!$C$7*EXP(-((((Model!$C$5*(($C$10)+Model!$C$6*($C$11)))-($C$16))/Model!$C$7)^2)/2)/SQRT(2*PI()))-(((Model!$C$5*(($C$10)+Model!$C$6*($C$11)))-($C$17))*NORMSDIST(((Model!$C$5*(($C$10)+Model!$C$6*($C$11)))-($C$17))/Model!$C$7)+Model!$C$7*EXP(-((((Model!$C$5*(($C$10)+Model!$C$6*($C$11)))-($C$17))/Model!$C$7)^2)/2)/SQRT(2*PI()))))) -> 1055.6838 | F38: =$C$12+$C$14*((Model!$C$5*(($B38)+Model!$C$6*(F$35)))-(Model!$C$5*(($C$10)+Model!$C$6*($C$11)))-$C$15*(((((Model!$C$5*(($B38)+Model!$C$6*(F$35)))-($C$16))*NORMSDIST(((Model!$C$5*(($B38)+Model!$C$6*(F$35)))-($C$16))/Model!$C$7)+Model!$C$7*EXP(-((((Model!$C$5*(($B38)+Model!$C$6*(F$35)))-($C$16))/Model!$C$7)^2)/2)/SQRT(2*PI()))-(((Model!$C$5*(($B38)+Model!$C$6*(F$35)))-($C$17))*NORMSDIST(((Model!$C$5*(($B38)+Model!$C$6*(F$35)))-($C$17))/Model!$C$7)+Model!$C$7*EXP(-((((Model!$C$5*(($B38)+Model!$C$6*(F$35)))-($C$17))/Model!$C$7)^2)/2)/SQRT(2*PI())))-((((Model!$C$5*(($C$10)+Model!$C$6*($C$11)))-($C$16))*NORMSDIST(((Model!$C$5*(($C$10)+Model!$C$6*($C$11)))-($C$16))/Model!$C$7)+Model!$C$7*EXP(-((((Model!$C$5*(($C$10)+Model!$C$6*($C$11)))-($C$16))/Model!$C$7)^2)/2)/SQRT(2*PI()))-(((Model!$C$5*(($C$10)+Model!$C$6*($C$11)))-($C$17))*NORMSDIST(((Model!$C$5*(($C$10)+Model!$C$6*($C$11)))-($C$17))/Model!$C$7)+Model!$C$7*EXP(-((((Model!$C$5*(($C$10)+Model!$C$6*($C$11)))-($C$17))/Model!$C$7)^2)/2)/SQRT(2*PI()))))) -> 1083.9042 | G38: =$C$12+$C$14*((Model!$C$5*(($B38)+Model!$C$6*(G$35)))-(Model!$C$5*(($C$10)+Model!$C$6*($C$11)))-$C$15*(((((Model!$C$5*(($B38)+Model!$C$6*(G$35)))-($C$16))*NORMSDIST(((Model!$C$5*(($B38)+Model!$C$6*(G$35)))-($C$16))/Model!$C$7)+Model!$C$7*EXP(-((((Model!$C$5*(($B38)+Model!$C$6*(G$35)))-($C$16))/Model!$C$7)^2)/2)/SQRT(2*PI()))-(((Model!$C$5*(($B38)+Model!$C$6*(G$35)))-($C$17))*NORMSDIST(((Model!$C$5*(($B38)+Model!$C$6*(G$35)))-($C$17))/Model!$C$7)+Model!$C$7*EXP(-((((Model!$C$5*(($B38)+Model!$C$6*(G$35)))-($C$17))/Model!$C$7)^2)/2)/SQRT(2*PI())))-((((Model!$C$5*(($C$10)+Model!$C$6*($C$11)))-($C$16))*NORMSDIST(((Model!$C$5*(($C$10)+Model!$C$6*($C$11)))-($C$16))/Model!$C$7)+Model!$C$7*EXP(-((((Model!$C$5*(($C$10)+Model!$C$6*($C$11)))-($C$16))/Model!$C$7)^2)/2)/SQRT(2*PI()))-(((Model!$C$5*(($C$10)+Model!$C$6*($C$11)))-($C$17))*NORMSDIST(((Model!$C$5*(($C$10)+Model!$C$6*($C$11)))-($C$17))/Model!$C$7)+Model!$C$7*EXP(-((((Model!$C$5*(($C$10)+Model!$C$6*($C$11)))-($C$17))/Model!$C$7)^2)/2)/SQRT(2*PI()))))) -> 1117.3522
B39: =$C$10+(0) -> 84 | C39: =$C$12+$C$14*((Model!$C$5*(($B39)+Model!$C$6*(C$35)))-(Model!$C$5*(($C$10)+Model!$C$6*($C$11)))-$C$15*(((((Model!$C$5*(($B39)+Model!$C$6*(C$35)))-($C$16))*NORMSDIST(((Model!$C$5*(($B39)+Model!$C$6*(C$35)))-($C$16))/Model!$C$7)+Model!$C$7*EXP(-((((Model!$C$5*(($B39)+Model!$C$6*(C$35)))-($C$16))/Model!$C$7)^2)/2)/SQRT(2*PI()))-(((Model!$C$5*(($B39)+Model!$C$6*(C$35)))-($C$17))*NORMSDIST(((Model!$C$5*(($B39)+Model!$C$6*(C$35)))-($C$17))/Model!$C$7)+Model!$C$7*EXP(-((((Model!$C$5*(($B39)+Model!$C$6*(C$35)))-($C$17))/Model!$C$7)^2)/2)/SQRT(2*PI())))-((((Model!$C$5*(($C$10)+Model!$C$6*($C$11)))-($C$16))*NORMSDIST(((Model!$C$5*(($C$10)+Model!$C$6*($C$11)))-($C$16))/Model!$C$7)+Model!$C$7*EXP(-((((Model!$C$5*(($C$10)+Model!$C$6*($C$11)))-($C$16))/Model!$C$7)^2)/2)/SQRT(2*PI()))-(((Model!$C$5*(($C$10)+Model!$C$6*($C$11)))-($C$17))*NORMSDIST(((Model!$C$5*(($C$10)+Model!$C$6*($C$11)))-($C$17))/Model!$C$7)+Model!$C$7*EXP(-((((Model!$C$5*(($C$10)+Model!$C$6*($C$11)))-($C$17))/Model!$C$7)^2)/2)/SQRT(2*PI()))))) -> 1006.7238 | D39: =$C$12+$C$14*((Model!$C$5*(($B39)+Model!$C$6*(D$35)))-(Model!$C$5*(($C$10)+Model!$C$6*($C$11)))-$C$15*(((((Model!$C$5*(($B39)+Model!$C$6*(D$35)))-($C$16))*NORMSDIST(((Model!$C$5*(($B39)+Model!$C$6*(D$35)))-($C$16))/Model!$C$7)+Model!$C$7*EXP(-((((Model!$C$5*(($B39)+Model!$C$6*(D$35)))-($C$16))/Model!$C$7)^2)/2)/SQRT(2*PI()))-(((Model!$C$5*(($B39)+Model!$C$6*(D$35)))-($C$17))*NORMSDIST(((Model!$C$5*(($B39)+Model!$C$6*(D$35)))-($C$17))/Model!$C$7)+Model!$C$7*EXP(-((((Model!$C$5*(($B39)+Model!$C$6*(D$35)))-($C$17))/Model!$C$7)^2)/2)/SQRT(2*PI())))-((((Model!$C$5*(($C$10)+Model!$C$6*($C$11)))-($C$16))*NORMSDIST(((Model!$C$5*(($C$10)+Model!$C$6*($C$11)))-($C$16))/Model!$C$7)+Model!$C$7*EXP(-((((Model!$C$5*(($C$10)+Model!$C$6*($C$11)))-($C$16))/Model!$C$7)^2)/2)/SQRT(2*PI()))-(((Model!$C$5*(($C$10)+Model!$C$6*($C$11)))-($C$17))*NORMSDIST(((Model!$C$5*(($C$10)+Model!$C$6*($C$11)))-($C$17))/Model!$C$7)+Model!$C$7*EXP(-((((Model!$C$5*(($C$10)+Model!$C$6*($C$11)))-($C$17))/Model!$C$7)^2)/2)/SQRT(2*PI()))))) -> 1019.3221 | E39: =$C$12+$C$14*((Model!$C$5*(($B39)+Model!$C$6*(E$35)))-(Model!$C$5*(($C$10)+Model!$C$6*($C$11)))-$C$15*(((((Model!$C$5*(($B39)+Model!$C$6*(E$35)))-($C$16))*NORMSDIST(((Model!$C$5*(($B39)+Model!$C$6*(E$35)))-($C$16))/Model!$C$7)+Model!$C$7*EXP(-((((Model!$C$5*(($B39)+Model!$C$6*(E$35)))-($C$16))/Model!$C$7)^2)/2)/SQRT(2*PI()))-(((Model!$C$5*(($B39)+Model!$C$6*(E$35)))-($C$17))*NORMSDIST(((Model!$C$5*(($B39)+Model!$C$6*(E$35)))-($C$17))/Model!$C$7)+Model!$C$7*EXP(-((((Model!$C$5*(($B39)+Model!$C$6*(E$35)))-($C$17))/Model!$C$7)^2)/2)/SQRT(2*PI())))-((((Model!$C$5*(($C$10)+Model!$C$6*($C$11)))-($C$16))*NORMSDIST(((Model!$C$5*(($C$10)+Model!$C$6*($C$11)))-($C$16))/Model!$C$7)+Model!$C$7*EXP(-((((Model!$C$5*(($C$10)+Model!$C$6*($C$11)))-($C$16))/Model!$C$7)^2)/2)/SQRT(2*PI()))-(((Model!$C$5*(($C$10)+Model!$C$6*($C$11)))-($C$17))*NORMSDIST(((Model!$C$5*(($C$10)+Model!$C$6*($C$11)))-($C$17))/Model!$C$7)+Model!$C$7*EXP(-((((Model!$C$5*(($C$10)+Model!$C$6*($C$11)))-($C$17))/Model!$C$7)^2)/2)/SQRT(2*PI()))))) -> 1036.2086 | F39: =$C$12+$C$14*((Model!$C$5*(($B39)+Model!$C$6*(F$35)))-(Model!$C$5*(($C$10)+Model!$C$6*($C$11)))-$C$15*(((((Model!$C$5*(($B39)+Model!$C$6*(F$35)))-($C$16))*NORMSDIST(((Model!$C$5*(($B39)+Model!$C$6*(F$35)))-($C$16))/Model!$C$7)+Model!$C$7*EXP(-((((Model!$C$5*(($B39)+Model!$C$6*(F$35)))-($C$16))/Model!$C$7)^2)/2)/SQRT(2*PI()))-(((Model!$C$5*(($B39)+Model!$C$6*(F$35)))-($C$17))*NORMSDIST(((Model!$C$5*(($B39)+Model!$C$6*(F$35)))-($C$17))/Model!$C$7)+Model!$C$7*EXP(-((((Model!$C$5*(($B39)+Model!$C$6*(F$35)))-($C$17))/Model!$C$7)^2)/2)/SQRT(2*PI())))-((((Model!$C$5*(($C$10)+Model!$C$6*($C$11)))-($C$16))*NORMSDIST(((Model!$C$5*(($C$10)+Model!$C$6*($C$11)))-($C$16))/Model!$C$7)+Model!$C$7*EXP(-((((Model!$C$5*(($C$10)+Model!$C$6*($C$11)))-($C$16))/Model!$C$7)^2)/2)/SQRT(2*PI()))-(((Model!$C$5*(($C$10)+Model!$C$6*($C$11)))-($C$17))*NORMSDIST(((Model!$C$5*(($C$10)+Model!$C$6*($C$11)))-($C$17))/Model!$C$7)+Model!$C$7*EXP(-((((Model!$C$5*(($C$10)+Model!$C$6*($C$11)))-($C$17))/Model!$C$7)^2)/2)/SQRT(2*PI()))))) -> 1059.0198 | G39: =$C$12+$C$14*((Model!$C$5*(($B39)+Model!$C$6*(G$35)))-(Model!$C$5*(($C$10)+Model!$C$6*($C$11)))-$C$15*(((((Model!$C$5*(($B39)+Model!$C$6*(G$35)))-($C$16))*NORMSDIST(((Model!$C$5*(($B39)+Model!$C$6*(G$35)))-($C$16))/Model!$C$7)+Model!$C$7*EXP(-((((Model!$C$5*(($B39)+Model!$C$6*(G$35)))-($C$16))/Model!$C$7)^2)/2)/SQRT(2*PI()))-(((Model!$C$5*(($B39)+Model!$C$6*(G$35)))-($C$17))*NORMSDIST(((Model!$C$5*(($B39)+Model!$C$6*(G$35)))-($C$17))/Model!$C$7)+Model!$C$7*EXP(-((((Model!$C$5*(($B39)+Model!$C$6*(G$35)))-($C$17))/Model!$C$7)^2)/2)/SQRT(2*PI())))-((((Model!$C$5*(($C$10)+Model!$C$6*($C$11)))-($C$16))*NORMSDIST(((Model!$C$5*(($C$10)+Model!$C$6*($C$11)))-($C$16))/Model!$C$7)+Model!$C$7*EXP(-((((Model!$C$5*(($C$10)+Model!$C$6*($C$11)))-($C$16))/Model!$C$7)^2)/2)/SQRT(2*PI()))-(((Model!$C$5*(($C$10)+Model!$C$6*($C$11)))-($C$17))*NORMSDIST(((Model!$C$5*(($C$10)+Model!$C$6*($C$11)))-($C$17))/Model!$C$7)+Model!$C$7*EXP(-((((Model!$C$5*(($C$10)+Model!$C$6*($C$11)))-($C$17))/Model!$C$7)^2)/2)/SQRT(2*PI()))))) -> 1088.005
B40: =$C$10+(-10) -> 74 | C40: =$C$12+$C$14*((Model!$C$5*(($B40)+Model!$C$6*(C$35)))-(Model!$C$5*(($C$10)+Model!$C$6*($C$11)))-$C$15*(((((Model!$C$5*(($B40)+Model!$C$6*(C$35)))-($C$16))*NORMSDIST(((Model!$C$5*(($B40)+Model!$C$6*(C$35)))-($C$16))/Model!$C$7)+Model!$C$7*EXP(-((((Model!$C$5*(($B40)+Model!$C$6*(C$35)))-($C$16))/Model!$C$7)^2)/2)/SQRT(2*PI()))-(((Model!$C$5*(($B40)+Model!$C$6*(C$35)))-($C$17))*NORMSDIST(((Model!$C$5*(($B40)+Model!$C$6*(C$35)))-($C$17))/Model!$C$7)+Model!$C$7*EXP(-((((Model!$C$5*(($B40)+Model!$C$6*(C$35)))-($C$17))/Model!$C$7)^2)/2)/SQRT(2*PI())))-((((Model!$C$5*(($C$10)+Model!$C$6*($C$11)))-($C$16))*NORMSDIST(((Model!$C$5*(($C$10)+Model!$C$6*($C$11)))-($C$16))/Model!$C$7)+Model!$C$7*EXP(-((((Model!$C$5*(($C$10)+Model!$C$6*($C$11)))-($C$16))/Model!$C$7)^2)/2)/SQRT(2*PI()))-(((Model!$C$5*(($C$10)+Model!$C$6*($C$11)))-($C$17))*NORMSDIST(((Model!$C$5*(($C$10)+Model!$C$6*($C$11)))-($C$17))/Model!$C$7)+Model!$C$7*EXP(-((((Model!$C$5*(($C$10)+Model!$C$6*($C$11)))-($C$17))/Model!$C$7)^2)/2)/SQRT(2*PI()))))) -> 997.39512 | D40: =$C$12+$C$14*((Model!$C$5*(($B40)+Model!$C$6*(D$35)))-(Model!$C$5*(($C$10)+Model!$C$6*($C$11)))-$C$15*(((((Model!$C$5*(($B40)+Model!$C$6*(D$35)))-($C$16))*NORMSDIST(((Model!$C$5*(($B40)+Model!$C$6*(D$35)))-($C$16))/Model!$C$7)+Model!$C$7*EXP(-((((Model!$C$5*(($B40)+Model!$C$6*(D$35)))-($C$16))/Model!$C$7)^2)/2)/SQRT(2*PI()))-(((Model!$C$5*(($B40)+Model!$C$6*(D$35)))-($C$17))*NORMSDIST(((Model!$C$5*(($B40)+Model!$C$6*(D$35)))-($C$17))/Model!$C$7)+Model!$C$7*EXP(-((((Model!$C$5*(($B40)+Model!$C$6*(D$35)))-($C$17))/Model!$C$7)^2)/2)/SQRT(2*PI())))-((((Model!$C$5*(($C$10)+Model!$C$6*($C$11)))-($C$16))*NORMSDIST(((Model!$C$5*(($C$10)+Model!$C$6*($C$11)))-($C$16))/Model!$C$7)+Model!$C$7*EXP(-((((Model!$C$5*(($C$10)+Model!$C$6*($C$11)))-($C$16))/Model!$C$7)^2)/2)/SQRT(2*PI()))-(((Model!$C$5*(($C$10)+Model!$C$6*($C$11)))-($C$17))*NORMSDIST(((Model!$C$5*(($C$10)+Model!$C$6*($C$11)))-($C$17))/Model!$C$7)+Model!$C$7*EXP(-((((Model!$C$5*(($C$10)+Model!$C$6*($C$11)))-($C$17))/Model!$C$7)^2)/2)/SQRT(2*PI()))))) -> 1008.205 | E40: =$C$12+$C$14*((Model!$C$5*(($B40)+Model!$C$6*(E$35)))-(Model!$C$5*(($C$10)+Model!$C$6*($C$11)))-$C$15*(((((Model!$C$5*(($B40)+Model!$C$6*(E$35)))-($C$16))*NORMSDIST(((Model!$C$5*(($B40)+Model!$C$6*(E$35)))-($C$16))/Model!$C$7)+Model!$C$7*EXP(-((((Model!$C$5*(($B40)+Model!$C$6*(E$35)))-($C$16))/Model!$C$7)^2)/2)/SQRT(2*PI()))-(((Model!$C$5*(($B40)+Model!$C$6*(E$35)))-($C$17))*NORMSDIST(((Model!$C$5*(($B40)+Model!$C$6*(E$35)))-($C$17))/Model!$C$7)+Model!$C$7*EXP(-((((Model!$C$5*(($B40)+Model!$C$6*(E$35)))-($C$17))/Model!$C$7)^2)/2)/SQRT(2*PI())))-((((Model!$C$5*(($C$10)+Model!$C$6*($C$11)))-($C$16))*NORMSDIST(((Model!$C$5*(($C$10)+Model!$C$6*($C$11)))-($C$16))/Model!$C$7)+Model!$C$7*EXP(-((((Model!$C$5*(($C$10)+Model!$C$6*($C$11)))-($C$16))/Model!$C$7)^2)/2)/SQRT(2*PI()))-(((Model!$C$5*(($C$10)+Model!$C$6*($C$11)))-($C$17))*NORMSDIST(((Model!$C$5*(($C$10)+Model!$C$6*($C$11)))-($C$17))/Model!$C$7)+Model!$C$7*EXP(-((((Model!$C$5*(($C$10)+Model!$C$6*($C$11)))-($C$17))/Model!$C$7)^2)/2)/SQRT(2*PI()))))) -> 1021.2358 | F40: =$C$12+$C$14*((Model!$C$5*(($B40)+Model!$C$6*(F$35)))-(Model!$C$5*(($C$10)+Model!$C$6*($C$11)))-$C$15*(((((Model!$C$5*(($B40)+Model!$C$6*(F$35)))-($C$16))*NORMSDIST(((Model!$C$5*(($B40)+Model!$C$6*(F$35)))-($C$16))/Model!$C$7)+Model!$C$7*EXP(-((((Model!$C$5*(($B40)+Model!$C$6*(F$35)))-($C$16))/Model!$C$7)^2)/2)/SQRT(2*PI()))-(((Model!$C$5*(($B40)+Model!$C$6*(F$35)))-($C$17))*NORMSDIST(((Model!$C$5*(($B40)+Model!$C$6*(F$35)))-($C$17))/Model!$C$7)+Model!$C$7*EXP(-((((Model!$C$5*(($B40)+Model!$C$6*(F$35)))-($C$17))/Model!$C$7)^2)/2)/SQRT(2*PI())))-((((Model!$C$5*(($C$10)+Model!$C$6*($C$11)))-($C$16))*NORMSDIST(((Model!$C$5*(($C$10)+Model!$C$6*($C$11)))-($C$16))/Model!$C$7)+Model!$C$7*EXP(-((((Model!$C$5*(($C$10)+Model!$C$6*($C$11)))-($C$16))/Model!$C$7)^2)/2)/SQRT(2*PI()))-(((Model!$C$5*(($C$10)+Model!$C$6*($C$11)))-($C$17))*NORMSDIST(((Model!$C$5*(($C$10)+Model!$C$6*($C$11)))-($C$17))/Model!$C$7)+Model!$C$7*EXP(-((((Model!$C$5*(($C$10)+Model!$C$6*($C$11)))-($C$17))/Model!$C$7)^2)/2)/SQRT(2*PI()))))) -> 1038.827 | G40: =$C$12+$C$14*((Model!$C$5*(($B40)+Model!$C$6*(G$35)))-(Model!$C$5*(($C$10)+Model!$C$6*($C$11)))-$C$15*(((((Model!$C$5*(($B40)+Model!$C$6*(G$35)))-($C$16))*NORMSDIST(((Model!$C$5*(($B40)+Model!$C$6*(G$35)))-($C$16))/Model!$C$7)+Model!$C$7*EXP(-((((Model!$C$5*(($B40)+Model!$C$6*(G$35)))-($C$16))/Model!$C$7)^2)/2)/SQRT(2*PI()))-(((Model!$C$5*(($B40)+Model!$C$6*(G$35)))-($C$17))*NORMSDIST(((Model!$C$5*(($B40)+Model!$C$6*(G$35)))-($C$17))/Model!$C$7)+Model!$C$7*EXP(-((((Model!$C$5*(($B40)+Model!$C$6*(G$35)))-($C$17))/Model!$C$7)^2)/2)/SQRT(2*PI())))-((((Model!$C$5*(($C$10)+Model!$C$6*($C$11)))-($C$16))*NORMSDIST(((Model!$C$5*(($C$10)+Model!$C$6*($C$11)))-($C$16))/Model!$C$7)+Model!$C$7*EXP(-((((Model!$C$5*(($C$10)+Model!$C$6*($C$11)))-($C$16))/Model!$C$7)^2)/2)/SQRT(2*PI()))-(((Model!$C$5*(($C$10)+Model!$C$6*($C$11)))-($C$17))*NORMSDIST(((Model!$C$5*(($C$10)+Model!$C$6*($C$11)))-($C$17))/Model!$C$7)+Model!$C$7*EXP(-((((Model!$C$5*(($C$10)+Model!$C$6*($C$11)))-($C$17))/Model!$C$7)^2)/2)/SQRT(2*PI()))))) -> 1062.463
B41: =$C$10+(-20) -> 64 | C41: =$C$12+$C$14*((Model!$C$5*(($B41)+Model!$C$6*(C$35)))-(Model!$C$5*(($C$10)+Model!$C$6*($C$11)))-$C$15*(((((Model!$C$5*(($B41)+Model!$C$6*(C$35)))-($C$16))*NORMSDIST(((Model!$C$5*(($B41)+Model!$C$6*(C$35)))-($C$16))/Model!$C$7)+Model!$C$7*EXP(-((((Model!$C$5*(($B41)+Model!$C$6*(C$35)))-($C$16))/Model!$C$7)^2)/2)/SQRT(2*PI()))-(((Model!$C$5*(($B41)+Model!$C$6*(C$35)))-($C$17))*NORMSDIST(((Model!$C$5*(($B41)+Model!$C$6*(C$35)))-($C$17))/Model!$C$7)+Model!$C$7*EXP(-((((Model!$C$5*(($B41)+Model!$C$6*(C$35)))-($C$17))/Model!$C$7)^2)/2)/SQRT(2*PI())))-((((Model!$C$5*(($C$10)+Model!$C$6*($C$11)))-($C$16))*NORMSDIST(((Model!$C$5*(($C$10)+Model!$C$6*($C$11)))-($C$16))/Model!$C$7)+Model!$C$7*EXP(-((((Model!$C$5*(($C$10)+Model!$C$6*($C$11)))-($C$16))/Model!$C$7)^2)/2)/SQRT(2*PI()))-(((Model!$C$5*(($C$10)+Model!$C$6*($C$11)))-($C$17))*NORMSDIST(((Model!$C$5*(($C$10)+Model!$C$6*($C$11)))-($C$17))/Model!$C$7)+Model!$C$7*EXP(-((((Model!$C$5*(($C$10)+Model!$C$6*($C$11)))-($C$17))/Model!$C$7)^2)/2)/SQRT(2*PI()))))) -> 987.77824 | D41: =$C$12+$C$14*((Model!$C$5*(($B41)+Model!$C$6*(D$35)))-(Model!$C$5*(($C$10)+Model!$C$6*($C$11)))-$C$15*(((((Model!$C$5*(($B41)+Model!$C$6*(D$35)))-($C$16))*NORMSDIST(((Model!$C$5*(($B41)+Model!$C$6*(D$35)))-($C$16))/Model!$C$7)+Model!$C$7*EXP(-((((Model!$C$5*(($B41)+Model!$C$6*(D$35)))-($C$16))/Model!$C$7)^2)/2)/SQRT(2*PI()))-(((Model!$C$5*(($B41)+Model!$C$6*(D$35)))-($C$17))*NORMSDIST(((Model!$C$5*(($B41)+Model!$C$6*(D$35)))-($C$17))/Model!$C$7)+Model!$C$7*EXP(-((((Model!$C$5*(($B41)+Model!$C$6*(D$35)))-($C$17))/Model!$C$7)^2)/2)/SQRT(2*PI())))-((((Model!$C$5*(($C$10)+Model!$C$6*($C$11)))-($C$16))*NORMSDIST(((Model!$C$5*(($C$10)+Model!$C$6*($C$11)))-($C$16))/Model!$C$7)+Model!$C$7*EXP(-((((Model!$C$5*(($C$10)+Model!$C$6*($C$11)))-($C$16))/Model!$C$7)^2)/2)/SQRT(2*PI()))-(((Model!$C$5*(($C$10)+Model!$C$6*($C$11)))-($C$17))*NORMSDIST(((Model!$C$5*(($C$10)+Model!$C$6*($C$11)))-($C$17))/Model!$C$7)+Model!$C$7*EXP(-((((Model!$C$5*(($C$10)+Model!$C$6*($C$11)))-($C$17))/Model!$C$7)^2)/2)/SQRT(2*PI()))))) -> 998.77053 | E41: =$C$12+$C$14*((Model!$C$5*(($B41)+Model!$C$6*(E$35)))-(Model!$C$5*(($C$10)+Model!$C$6*($C$11)))-$C$15*(((((Model!$C$5*(($B41)+Model!$C$6*(E$35)))-($C$16))*NORMSDIST(((Model!$C$5*(($B41)+Model!$C$6*(E$35)))-($C$16))/Model!$C$7)+Model!$C$7*EXP(-((((Model!$C$5*(($B41)+Model!$C$6*(E$35)))-($C$16))/Model!$C$7)^2)/2)/SQRT(2*PI()))-(((Model!$C$5*(($B41)+Model!$C$6*(E$35)))-($C$17))*NORMSDIST(((Model!$C$5*(($B41)+Model!$C$6*(E$35)))-($C$17))/Model!$C$7)+Model!$C$7*EXP(-((((Model!$C$5*(($B41)+Model!$C$6*(E$35)))-($C$17))/Model!$C$7)^2)/2)/SQRT(2*PI())))-((((Model!$C$5*(($C$10)+Model!$C$6*($C$11)))-($C$16))*NORMSDIST(((Model!$C$5*(($C$10)+Model!$C$6*($C$11)))-($C$16))/Model!$C$7)+Model!$C$7*EXP(-((((Model!$C$5*(($C$10)+Model!$C$6*($C$11)))-($C$16))/Model!$C$7)^2)/2)/SQRT(2*PI()))-(((Model!$C$5*(($C$10)+Model!$C$6*($C$11)))-($C$17))*NORMSDIST(((Model!$C$5*(($C$10)+Model!$C$6*($C$11)))-($C$17))/Model!$C$7)+Model!$C$7*EXP(-((((Model!$C$5*(($C$10)+Model!$C$6*($C$11)))-($C$17))/Model!$C$7)^2)/2)/SQRT(2*PI()))))) -> 1009.7243 | F41: =$C$12+$C$14*((Model!$C$5*(($B41)+Model!$C$6*(F$35)))-(Model!$C$5*(($C$10)+Model!$C$6*($C$11)))-$C$15*(((((Model!$C$5*(($B41)+Model!$C$6*(F$35)))-($C$16))*NORMSDIST(((Model!$C$5*(($B41)+Model!$C$6*(F$35)))-($C$16))/Model!$C$7)+Model!$C$7*EXP(-((((Model!$C$5*(($B41)+Model!$C$6*(F$35)))-($C$16))/Model!$C$7)^2)/2)/SQRT(2*PI()))-(((Model!$C$5*(($B41)+Model!$C$6*(F$35)))-($C$17))*NORMSDIST(((Model!$C$5*(($B41)+Model!$C$6*(F$35)))-($C$17))/Model!$C$7)+Model!$C$7*EXP(-((((Model!$C$5*(($B41)+Model!$C$6*(F$35)))-($C$17))/Model!$C$7)^2)/2)/SQRT(2*PI())))-((((Model!$C$5*(($C$10)+Model!$C$6*($C$11)))-($C$16))*NORMSDIST(((Model!$C$5*(($C$10)+Model!$C$6*($C$11)))-($C$16))/Model!$C$7)+Model!$C$7*EXP(-((((Model!$C$5*(($C$10)+Model!$C$6*($C$11)))-($C$16))/Model!$C$7)^2)/2)/SQRT(2*PI()))-(((Model!$C$5*(($C$10)+Model!$C$6*($C$11)))-($C$17))*NORMSDIST(((Model!$C$5*(($C$10)+Model!$C$6*($C$11)))-($C$17))/Model!$C$7)+Model!$C$7*EXP(-((((Model!$C$5*(($C$10)+Model!$C$6*($C$11)))-($C$17))/Model!$C$7)^2)/2)/SQRT(2*PI()))))) -> 1023.2283 | G41: =$C$12+$C$14*((Model!$C$5*(($B41)+Model!$C$6*(G$35)))-(Model!$C$5*(($C$10)+Model!$C$6*($C$11)))-$C$15*(((((Model!$C$5*(($B41)+Model!$C$6*(G$35)))-($C$16))*NORMSDIST(((Model!$C$5*(($B41)+Model!$C$6*(G$35)))-($C$16))/Model!$C$7)+Model!$C$7*EXP(-((((Model!$C$5*(($B41)+Model!$C$6*(G$35)))-($C$16))/Model!$C$7)^2)/2)/SQRT(2*PI()))-(((Model!$C$5*(($B41)+Model!$C$6*(G$35)))-($C$17))*NORMSDIST(((Model!$C$5*(($B41)+Model!$C$6*(G$35)))-($C$17))/Model!$C$7)+Model!$C$7*EXP(-((((Model!$C$5*(($B41)+Model!$C$6*(G$35)))-($C$17))/Model!$C$7)^2)/2)/SQRT(2*PI())))-((((Model!$C$5*(($C$10)+Model!$C$6*($C$11)))-($C$16))*NORMSDIST(((Model!$C$5*(($C$10)+Model!$C$6*($C$11)))-($C$16))/Model!$C$7)+Model!$C$7*EXP(-((((Model!$C$5*(($C$10)+Model!$C$6*($C$11)))-($C$16))/Model!$C$7)^2)/2)/SQRT(2*PI()))-(((Model!$C$5*(($C$10)+Model!$C$6*($C$11)))-($C$17))*NORMSDIST(((Model!$C$5*(($C$10)+Model!$C$6*($C$11)))-($C$17))/Model!$C$7)+Model!$C$7*EXP(-((((Model!$C$5*(($C$10)+Model!$C$6*($C$11)))-($C$17))/Model!$C$7)^2)/2)/SQRT(2*PI()))))) -> 1041.5503
B42: =$C$10+(-30) -> 54 | C42: =$C$12+$C$14*((Model!$C$5*(($B42)+Model!$C$6*(C$35)))-(Model!$C$5*(($C$10)+Model!$C$6*($C$11)))-$C$15*(((((Model!$C$5*(($B42)+Model!$C$6*(C$35)))-($C$16))*NORMSDIST(((Model!$C$5*(($B42)+Model!$C$6*(C$35)))-($C$16))/Model!$C$7)+Model!$C$7*EXP(-((((Model!$C$5*(($B42)+Model!$C$6*(C$35)))-($C$16))/Model!$C$7)^2)/2)/SQRT(2*PI()))-(((Model!$C$5*(($B42)+Model!$C$6*(C$35)))-($C$17))*NORMSDIST(((Model!$C$5*(($B42)+Model!$C$6*(C$35)))-($C$17))/Model!$C$7)+Model!$C$7*EXP(-((((Model!$C$5*(($B42)+Model!$C$6*(C$35)))-($C$17))/Model!$C$7)^2)/2)/SQRT(2*PI())))-((((Model!$C$5*(($C$10)+Model!$C$6*($C$11)))-($C$16))*NORMSDIST(((Model!$C$5*(($C$10)+Model!$C$6*($C$11)))-($C$16))/Model!$C$7)+Model!$C$7*EXP(-((((Model!$C$5*(($C$10)+Model!$C$6*($C$11)))-($C$16))/Model!$C$7)^2)/2)/SQRT(2*PI()))-(((Model!$C$5*(($C$10)+Model!$C$6*($C$11)))-($C$17))*NORMSDIST(((Model!$C$5*(($C$10)+Model!$C$6*($C$11)))-($C$17))/Model!$C$7)+Model!$C$7*EXP(-((((Model!$C$5*(($C$10)+Model!$C$6*($C$11)))-($C$17))/Model!$C$7)^2)/2)/SQRT(2*PI()))))) -> 976.17293 | D42: =$C$12+$C$14*((Model!$C$5*(($B42)+Model!$C$6*(D$35)))-(Model!$C$5*(($C$10)+Model!$C$6*($C$11)))-$C$15*(((((Model!$C$5*(($B42)+Model!$C$6*(D$35)))-($C$16))*NORMSDIST(((Model!$C$5*(($B42)+Model!$C$6*(D$35)))-($C$16))/Model!$C$7)+Model!$C$7*EXP(-((((Model!$C$5*(($B42)+Model!$C$6*(D$35)))-($C$16))/Model!$C$7)^2)/2)/SQRT(2*PI()))-(((Model!$C$5*(($B42)+Model!$C$6*(D$35)))-($C$17))*NORMSDIST(((Model!$C$5*(($B42)+Model!$C$6*(D$35)))-($C$17))/Model!$C$7)+Model!$C$7*EXP(-((((Model!$C$5*(($B42)+Model!$C$6*(D$35)))-($C$17))/Model!$C$7)^2)/2)/SQRT(2*PI())))-((((Model!$C$5*(($C$10)+Model!$C$6*($C$11)))-($C$16))*NORMSDIST(((Model!$C$5*(($C$10)+Model!$C$6*($C$11)))-($C$16))/Model!$C$7)+Model!$C$7*EXP(-((((Model!$C$5*(($C$10)+Model!$C$6*($C$11)))-($C$16))/Model!$C$7)^2)/2)/SQRT(2*PI()))-(((Model!$C$5*(($C$10)+Model!$C$6*($C$11)))-($C$17))*NORMSDIST(((Model!$C$5*(($C$10)+Model!$C$6*($C$11)))-($C$17))/Model!$C$7)+Model!$C$7*EXP(-((((Model!$C$5*(($C$10)+Model!$C$6*($C$11)))-($C$17))/Model!$C$7)^2)/2)/SQRT(2*PI()))))) -> 989.3069 | E42: =$C$12+$C$14*((Model!$C$5*(($B42)+Model!$C$6*(E$35)))-(Model!$C$5*(($C$10)+Model!$C$6*($C$11)))-$C$15*(((((Model!$C$5*(($B42)+Model!$C$6*(E$35)))-($C$16))*NORMSDIST(((Model!$C$5*(($B42)+Model!$C$6*(E$35)))-($C$16))/Model!$C$7)+Model!$C$7*EXP(-((((Model!$C$5*(($B42)+Model!$C$6*(E$35)))-($C$16))/Model!$C$7)^2)/2)/SQRT(2*PI()))-(((Model!$C$5*(($B42)+Model!$C$6*(E$35)))-($C$17))*NORMSDIST(((Model!$C$5*(($B42)+Model!$C$6*(E$35)))-($C$17))/Model!$C$7)+Model!$C$7*EXP(-((((Model!$C$5*(($B42)+Model!$C$6*(E$35)))-($C$17))/Model!$C$7)^2)/2)/SQRT(2*PI())))-((((Model!$C$5*(($C$10)+Model!$C$6*($C$11)))-($C$16))*NORMSDIST(((Model!$C$5*(($C$10)+Model!$C$6*($C$11)))-($C$16))/Model!$C$7)+Model!$C$7*EXP(-((((Model!$C$5*(($C$10)+Model!$C$6*($C$11)))-($C$16))/Model!$C$7)^2)/2)/SQRT(2*PI()))-(((Model!$C$5*(($C$10)+Model!$C$6*($C$11)))-($C$17))*NORMSDIST(((Model!$C$5*(($C$10)+Model!$C$6*($C$11)))-($C$17))/Model!$C$7)+Model!$C$7*EXP(-((((Model!$C$5*(($C$10)+Model!$C$6*($C$11)))-($C$17))/Model!$C$7)^2)/2)/SQRT(2*PI()))))) -> 1000.1453 | F42: =$C$12+$C$14*((Model!$C$5*(($B42)+Model!$C$6*(F$35)))-(Model!$C$5*(($C$10)+Model!$C$6*($C$11)))-$C$15*(((((Model!$C$5*(($B42)+Model!$C$6*(F$35)))-($C$16))*NORMSDIST(((Model!$C$5*(($B42)+Model!$C$6*(F$35)))-($C$16))/Model!$C$7)+Model!$C$7*EXP(-((((Model!$C$5*(($B42)+Model!$C$6*(F$35)))-($C$16))/Model!$C$7)^2)/2)/SQRT(2*PI()))-(((Model!$C$5*(($B42)+Model!$C$6*(F$35)))-($C$17))*NORMSDIST(((Model!$C$5*(($B42)+Model!$C$6*(F$35)))-($C$17))/Model!$C$7)+Model!$C$7*EXP(-((((Model!$C$5*(($B42)+Model!$C$6*(F$35)))-($C$17))/Model!$C$7)^2)/2)/SQRT(2*PI())))-((((Model!$C$5*(($C$10)+Model!$C$6*($C$11)))-($C$16))*NORMSDIST(((Model!$C$5*(($C$10)+Model!$C$6*($C$11)))-($C$16))/Model!$C$7)+Model!$C$7*EXP(-((((Model!$C$5*(($C$10)+Model!$C$6*($C$11)))-($C$16))/Model!$C$7)^2)/2)/SQRT(2*PI()))-(((Model!$C$5*(($C$10)+Model!$C$6*($C$11)))-($C$17))*NORMSDIST(((Model!$C$5*(($C$10)+Model!$C$6*($C$11)))-($C$17))/Model!$C$7)+Model!$C$7*EXP(-((((Model!$C$5*(($C$10)+Model!$C$6*($C$11)))-($C$17))/Model!$C$7)^2)/2)/SQRT(2*PI()))))) -> 1011.2873 | G42: =$C$12+$C$14*((Model!$C$5*(($B42)+Model!$C$6*(G$35)))-(Model!$C$5*(($C$10)+Model!$C$6*($C$11)))-$C$15*(((((Model!$C$5*(($B42)+Model!$C$6*(G$35)))-($C$16))*NORMSDIST(((Model!$C$5*(($B42)+Model!$C$6*(G$35)))-($C$16))/Model!$C$7)+Model!$C$7*EXP(-((((Model!$C$5*(($B42)+Model!$C$6*(G$35)))-($C$16))/Model!$C$7)^2)/2)/SQRT(2*PI()))-(((Model!$C$5*(($B42)+Model!$C$6*(G$35)))-($C$17))*NORMSDIST(((Model!$C$5*(($B42)+Model!$C$6*(G$35)))-($C$17))/Model!$C$7)+Model!$C$7*EXP(-((((Model!$C$5*(($B42)+Model!$C$6*(G$35)))-($C$17))/Model!$C$7)^2)/2)/SQRT(2*PI())))-((((Model!$C$5*(($C$10)+Model!$C$6*($C$11)))-($C$16))*NORMSDIST(((Model!$C$5*(($C$10)+Model!$C$6*($C$11)))-($C$16))/Model!$C$7)+Model!$C$7*EXP(-((((Model!$C$5*(($C$10)+Model!$C$6*($C$11)))-($C$16))/Model!$C$7)^2)/2)/SQRT(2*PI()))-(((Model!$C$5*(($C$10)+Model!$C$6*($C$11)))-($C$17))*NORMSDIST(((Model!$C$5*(($C$10)+Model!$C$6*($C$11)))-($C$17))/Model!$C$7)+Model!$C$7*EXP(-((((Model!$C$5*(($C$10)+Model!$C$6*($C$11)))-($C$17))/Model!$C$7)^2)/2)/SQRT(2*PI()))))) -> 1025.304
B45: Hedge-ratio sweep (other inputs as above)
...

Sheet Recon 1H26
B1: Reconciliation with H1 2026 reported fuel figures
B2: Test: start from Lufthansa's own quarterly guidance, move unrealised months from guidance forwards to realised prices with the model, compare with reported fuel expense.
B4: Monthly market prices | C4: Jan | D4: Feb | E4: Mar | F4: Apr | G4: May | H4: Jun
B5: Brent spot, FRED MCOILBRENTEU ($/bbl) | C5: 66.6 | D5: 70.89 | E5: 103.13 | F5: 117.29 | G5: 107.14 | H5: 85.4
B6: Jet fuel USGC, FRED MJFUELUSGULF ($/gal) | C6: 2.031 | D6: 2.262 | E6: 3.697 | F6: 3.928 | G6: 3.943 | H6: 3.042
B7: LH H1 average Brent ($/bbl) | C7: 87.44
B8: LH H1 average kerosene ($/t) | C8: 1133.9
B9: Brent rebased to LH level ($/bbl) | C9: =C5*$C$7/AVERAGE($C$5:$H$5) -> 63.477199 | D9: =D5*$C$7/AVERAGE($C$5:$H$5) -> 67.566045 | E9: =E5*$C$7/AVERAGE($C$5:$H$5) -> 98.294347 | F9: =F5*$C$7/AVERAGE($C$5:$H$5) -> 111.7904 | G9: =G5*$C$7/AVERAGE($C$5:$H$5) -> 102.11632 | H9: =H5*$C$7/AVERAGE($C$5:$H$5) -> 81.395687
B10: Jet rebased to LH level ($/t) | C10: =C6*42*Model!$C$5*$C$8/(AVERAGE($C$6:$H$6)*42*Model!$C$5) -> 730.9795 | D10: =D6*42*Model!$C$5*$C$8/(AVERAGE($C$6:$H$6)*42*Model!$C$5) -> 814.11897 | E10: =E6*42*Model!$C$5*$C$8/(AVERAGE($C$6:$H$6)*42*Model!$C$5) -> 1330.5914 | F10: =F6*42*Model!$C$5*$C$8/(AVERAGE($C$6:$H$6)*42*Model!$C$5) -> 1413.7309 | G10: =G6*42*Model!$C$5*$C$8/(AVERAGE($C$6:$H$6)*42*Model!$C$5) -> 1419.1296 | H10: =H6*42*Model!$C$5*$C$8/(AVERAGE($C$6:$H$6)*42*Model!$C$5) -> 1094.8496
B11: Implied jet crack ($/bbl) | C11: =C10/Model!$C$5-C9 -> 29.286697 | D11: =D10/Model!$C$5-D9 -> 35.748544 | E11: =E10/Model!$C$5-E9 -> 70.562434 | F11: =F10/Model!$C$5-F9 -> 67.617075 | G11: =G10/Model!$C$5-G9 -> 77.976262 | H11: =H10/Model!$C$5-H9 -> 57.544623
B12: Model jet price J = k·(Brent + w·crack) ($/t) | C12: =Model!$C$5*((C9)+Model!$C$6*(C11)) -> 765.59637 | D12: =Model!$C$5*((D9)+Model!$C$6*(D11)) -> 856.37374 | E12: =Model!$C$5*((E9)+Model!$C$6*(E11)) -> 1413.9962 | F12: =Model!$C$5*((F9)+Model!$C$6*(F11)) -> 1493.6543 | G12: =Model!$C$5*((G9)+Model!$C$6*(G11)) -> 1511.2975 | H12: =Model!$C$5*((H9)+Model!$C$6*(H11)) -> 1162.8674
B13: Shape from FRED monthly series, level rebased to Lufthansa's H1 averages (FRED is US Gulf Coast jet and Europe Brent spot).
B15: Quarterly inputs (blue) and test
C16: Q1 2026 | D16: Q2 2026 | E16: H1 2026
B17: Guidance date | C17: 28 Feb 2026 | D17: 30 Apr 2026
B18: Guided post-hedge jet price ($/t) | C18: 853 | D18: 1263
B19: Guided volume (mt) | C19: 2 | D19: 2.4
B20: Guided mandatory SAF (€m) | C20: 40 | D20: 50
B21: Guided FX at guidance (USD/EUR) | C21: 1.18 | D21: 1.17
B22: Hedge ratio for the quarter (h) | C22: 0.82 | D22: 0.83
B23: Forward Brent at guidance, unrealised months ($/bbl) | C23: 70.6 | D23: 97.9
B24: Forward crack at guidance ($/bbl) | C24: 26.3 | D24: 59
B25: Realised FX (USD/EUR) | C25: 1.1664 | D25: 1.1664
B26: Reported fuel expense (€m) | C26: 1570 | D26: 2606 | E26: =C26+D26 -> 4176
B27: Reported hedge result (€m) | C27: 126 | D27: 459 | E27: =C27+D27 -> 585
B29: Guidance fuel cost (€m) | C29: =C19*C18/C21+C20 -> 1485.7627 | D29: =D19*D18/D21+D20 -> 2640.7692 | E29: =C29+D29 -> 4126.5319
B30: Forward model jet price J_fwd ($/t) | C30: =Model!$C$5*((C23)+Model!$C$6*(C24)) -> 794.6586 | D30: =Model!$C$5*((D23)+Model!$C$6*(D24)) -> 1306.11
B31: Unrealised months | C31: Mar | D31: May, Jun
B32: Model ΔP vs guidance ($/t) | C32: =(((E$12-C30)-C22*(((((E$12)-(Model!$C$16))*NORMSDIST(((E$12)-(Model!$C$16))/Model!$C$7)+Model!$C$7*EXP(-((((E$12)-(Model!$C$16))/Model!$C$7)^2)/2)/SQRT(2*PI()))-(((E$12)-(Model!$C$17))*NORMSDIST(((E$12)-(Model!$C$17))/Model!$C$7)+Model!$C$7*EXP(-((((E$12)-(Model!$C$17))/Model!$C$7)^2)/2)/SQRT(2*PI())))-((((C30)-(Model!$C$16))*NORMSDIST(((C30)-(Model!$C$16))/Model!$C$7)+Model!$C$7*EXP(-((((C30)-(Model!$C$16))/Model!$C$7)^2)/2)/SQRT(2*PI()))-(((C30)-(Model!$C$17))*NORMSDIST(((C30)-(Model!$C$17))/Model!$C$7)+Model!$C$7*EXP(-((((C30)-(Model!$C$17))/Model!$C$7)^2)/2)/SQRT(2*PI()))))))/3 -> 85.149734 | D32: =(((G$12-D30)-D22*(((((G$12)-(Model!$C$16))*NORMSDIST(((G$12)-(Model!$C$16))/Model!$C$7)+Model!$C$7*EXP(-((((G$12)-(Model!$C$16))/Model!$C$7)^2)/2)/SQRT(2*PI()))-(((G$12)-(Model!$C$17))*NORMSDIST(((G$12)-(Model!$C$17))/Model!$C$7)+Model!$C$7*EXP(-((((G$12)-(Model!$C$17))/Model!$C$7)^2)/2)/SQRT(2*PI())))-((((D30)-(Model!$C$16))*NORMSDIST(((D30)-(Model!$C$16))/Model!$C$7)+Model!$C$7*EXP(-((((D30)-(Model!$C$16))/Model!$C$7)^2)/2)/SQRT(2*PI()))-(((D30)-(Model!$C$17))*NORMSDIST(((D30)-(Model!$C$17))/Model!$C$7)+Model!$C$7*EXP(-((((D30)-(Model!$C$17))/Model!$C$7)^2)/2)/SQRT(2*PI())))))+((H$12-D30)-D22*(((((H$12)-(Model!$C$16))*NORMSDIST(((H$12)-(Model!$C$16))/Model!$C$7)+Model!$C$7*EXP(-((((H$12)-(Model!$C$16))/Model!$C$7)^2)/2)/SQRT(2*PI()))-(((H$12)-(Model!$C$17))*NORMSDIST(((H$12)-(Model!$C$17))/Model!$C$7)+Model!$C$7*EXP(-((((H$12)-(Model!$C$17))/Model!$C$7)^2)/2)/SQRT(2*PI())))-((((D30)-(Model!$C$16))*NORMSDIST(((D30)-(Model!$C$16))/Model!$C$7)+Model!$C$7*EXP(-((((D30)-(Model!$C$16))/Model!$C$7)^2)/2)/SQRT(2*PI()))-(((D30)-(Model!$C$17))*NORMSDIST(((D30)-(Model!$C$17))/Model!$C$7)+Model!$C$7*EXP(-((((D30)-(Model!$C$17))/Model!$C$7)^2)/2)/SQRT(2*PI()))))))/3 -> 29.743099
B33: MODEL fuel cost at realised prices (€m) | C33: =C19*(C18+C32)/C25+C20 -> 1648.6244 | D33: =D19*(D18+D32)/D25+D20 -> 2709.9652 | E33: =C33+D33 -> 4358.5896
B34: Error vs reported (€m) | C34: =C33-C26 -> 78.624373 | D34: =D33-D26 -> 103.96522 | E34: =E33-E26 -> 182.5896
B35: Error vs reported (%) | C35: =C34/C26 -> 0.050079218 | D35: =D34/D26 -> 0.03989456 | E35: =E34/E26 -> 0.043723563
B36: Model hedge payoff (€m, absolute) | C36: =C22*C19/3*((((C$12)-(Model!$C$16))*NORMSDIST(((C$12)-(Model!$C$16))/Model!$C$7)+Model!$C$7*EXP(-((((C$12)-(Model!$C$16))/Model!$C$7)^2)/2)/SQRT(2*PI()))-(((C$12)-(Model!$C$17))*NORMSDIST(((C$12)-(Model!$C$17))/Model!$C$7)+Model!$C$7*EXP(-((((C$12)-(Model!$C$17))/Model!$C$7)^2)/2)/SQRT(2*PI())))/C25+C22*C19/3*((((D$12)-(Model!$C$16))*NORMSDIST(((D$12)-(Model!$C$16))/Model!$C$7)+Model!$C$7*EXP(-((((D$12)-(Model!$C$16))/Model!$C$7)^2)/2)/SQRT(2*PI()))-(((D$12)-(Model!$C$17))*NORMSDIST(((D$12)-(Model!$C$17))/Model!$C$7)+Model!$C$7*EXP(-((((D$12)-(Model!$C$17))/Model!$C$7)^2)/2)/SQRT(2*PI())))/C25+C22*C19/3*((((E$12)-(Model!$C$16))*NORMSDIST(((E$12)-(Model!$C$16))/Model!$C$7)+Model!$C$7*EXP(-((((E$12)-(Model!$C$16))/Model!$C$7)^2)/2)/SQRT(2*PI()))-(((E$12)-(Model!$C$17))*NORMSDIST(((E$12)-(Model!$C$17))/Model!$C$7)+Model!$C$7*EXP(-((((E$12)-(Model!$C$17))/Model!$C$7)^2)/2)/SQRT(2*PI())))/C25 -> 411.18616 | D36: =D22*D19/3*((((F$12)-(Model!$C$16))*NORMSDIST(((F$12)-(Model!$C$16))/Model!$C$7)+Model!$C$7*EXP(-((((F$12)-(Model!$C$16))/Model!$C$7)^2)/2)/SQRT(2*PI()))-(((F$12)-(Model!$C$17))*NORMSDIST(((F$12)-(Model!$C$17))/Model!$C$7)+Model!$C$7*EXP(-((((F$12)-(Model!$C$17))/Model!$C$7)^2)/2)/SQRT(2*PI())))/D25+D22*D19/3*((((G$12)-(Model!$C$16))*NORMSDIST(((G$12)-(Model!$C$16))/Model!$C$7)+Model!$C$7*EXP(-((((G$12)-(Model!$C$16))/Model!$C$7)^2)/2)/SQRT(2*PI()))-(((G$12)-(Model!$C$17))*NORMSDIST(((G$12)-(Model!$C$17))/Model!$C$7)+Model!$C$7*EXP(-((((G$12)-(Model!$C$17))/Model!$C$7)^2)/2)/SQRT(2*PI())))/D25+D22*D19/3*((((H$12)-(Model!$C$16))*NORMSDIST(((H$12)-(Model!$C$16))/Model!$C$7)+Model!$C$7*EXP(-((((H$12)-(Model!$C$16))/Model!$C$7)^2)/2)/SQRT(2*PI()))-(((H$12)-(Model!$C$17))*NORMSDIST(((H$12)-(Model!$C$17))/Model!$C$7)+Model!$C$7*EXP(-((((H$12)-(Model!$C$17))/Model!$C$7)^2)/2)/SQRT(2*PI())))/D25 -> 934.00913 | E36: =C36+D36 -> 1345.1953
B37: Model hedge gain increase Q1→Q2 (€m) | C37: =D36-C36 -> 522.82297
B38: Reported increase Q1→Q2 (€m) | C38: =D27-C27 -> 333
B40: Reading the test:
B41: • Fuel cost: compare the yellow rows. Within roughly ±5% is as good as the inputs allow: quarterly volumes and FX are not disclosed (guided values used), and FRED is US Gulf Coast jet, rebased to Lufthansa's H1 average.
B42: • Absolute hedge payoff cannot be compared with the reported hedge result: the grid only pins how cost CHANGES with price, and option premiums and layering sit in P0.
B43: • The change in hedge gains between quarters can be compared: it tests whether the model's protection at high prices is right.

Sheet Calibration
B1: Calibration on published Lufthansa sensitivity grids
B2: Strikes are per hedge year (blue = calibrated values you can override). Global parameters live on the Model sheet.
B4: Hedge-year strikes | F4: Fit summary ($/t)
B5: Hedge year | C5: K1 ($/t) | D5: K2 ($/t) | F5: Grid (hedge year @ as-of) | G5: RMSE | H5: Max |error| | I5: Naive RMSE*
B6: 2026 | C6: 691 | D6: 1299 | F6: FY24@2024-10-22 | G6: =SQRT(SUMSQ(R30:V38)/COUNT(R30:V38)) -> 2.54555 | H6: =MAX(MAX(R30:V38),-MIN(R30:V38)) -> 6.9261855 | I6: =SQRT(C39/COUNT(R30:V38)) -> 20.542897
B7: 2025 | C7: 690 | D7: 1005 | F7: FY25@2025-02-28 | G7: =SQRT(SUMSQ(R55:V61)/COUNT(R55:V61)) -> 12.207854 | H7: =MAX(MAX(R55:V61),-MIN(R55:V61)) -> 29.260543 | I7: =SQRT(C62/COUNT(R55:V61)) -> 58.6927
B8: 2024 | C8: 900 | D8: 1345 | F8: FY25@2025-04-24 | G8: =SQRT(SUMSQ(R78:V84)/COUNT(R78:V84)) -> 13.535899 | H8: =MAX(MAX(R78:V84),-MIN(R78:V84)) -> 29.202747 | I8: =SQRT(C85/COUNT(R78:V84)) -> 65.044963
F9: FY25@2025-07-25 | G9: =SQRT(SUMSQ(R101:V107)/COUNT(R101:V107)) -> 7.9906082 | H9: =MAX(MAX(R101:V107),-MIN(R101:V107)) -> 20.156872 | I9: =SQRT(C108/COUNT(R101:V107)) -> 26.741635
F10: FY25@2025-10-24 | G10: =SQRT(SUMSQ(R124:V130)/COUNT(R124:V130)) -> 3.9934182 | H10: =MAX(MAX(R124:V130),-MIN(R124:V130)) -> 9.6726561 | I10: =SQRT(C131/COUNT(R124:V130)) -> 15.893985
F11: FY26@2026-02-28 | G11: =SQRT(SUMSQ(R147:V153)/COUNT(R147:V153)) -> 9.6749682 | H11: =MAX(MAX(R147:V153),-MIN(R147:V153)) -> 23.334455 | I11: =SQRT(C154/COUNT(R147:V153)) -> 43.616475
F12: FY26@2026-04-30 | G12: =SQRT(SUMSQ(R170:V176)/COUNT(R170:V176)) -> 10.57823 | H12: =MAX(MAX(R170:V176),-MIN(R170:V176)) -> 18.968005 | I12: =SQRT(C177/COUNT(R170:V176)) -> 53.543517
F13: FY26@2026-07-27 | G13: =SQRT(SUMSQ(R193:V199)/COUNT(R193:V199)) -> 6.3011204 | H13: =MAX(MAX(R193:V199),-MIN(R193:V199)) -> 13.390299 | I13: =SQRT(C200/COUNT(R193:V199)) -> 35.569146
F14: All grids | G14: =SQRT((SUMSQ(R30:V38)+SUMSQ(R55:V61)+SUMSQ(R78:V84)+SUMSQ(R101:V107)+SUMSQ(R124:V130)+SUMSQ(R147:V153)+SUMSQ(R170:V176)+SUMSQ(R193:V199))/(COUNT(R30:V38)+COUNT(R55:V61)+COUNT(R78:V84)+COUNT(R101:V107)+COUNT(R124:V130)+COUNT(R147:V153)+COUNT(R170:V176)+COUNT(R193:V199))) -> 8.9626823 | H14: =MAX(H6:H13) -> 29.260543 | I14: =SQRT((C39+C62+C85+C108+C131+C154+C177+C200)/(COUNT(R30:V38)+COUNT(R55:V61)+COUNT(R78:V84)+COUNT(R101:V107)+COUNT(R124:V130)+COUNT(R147:V153)+COUNT(R170:V176)+COUNT(R193:V199))) -> 42.859691
F15: *Naive = P0 + s·(1−h)·ΔJ, i.e. treating the hedge ratio as a straight swap hedge.
B17: FY24@2024-10-22 | C17: Source: Q3 2024 results presentation
B18: Hedge year | C18: 2024
B19: Months not yet realised | C19: 2
B20: s | C20: =C19/12 -> 0.16666667
B21: Hedge ratio h | C21: 0.83
B22: Base Brent | C22: 76
B23: Base crack | C23: 15
B24: P0 (centre cell) | C24: =INDEX(D30:H38,MATCH(C22,C30:C38,0),MATCH(C23,D29:H29,0)) -> 888
B25: K1 | C25: =INDEX($C$6:$C$8,MATCH(C18,$B$6:$B$8,0)) -> 900
B26: K2 | C26: =INDEX($D$6:$D$8,MATCH(C18,$B$6:$B$8,0)) -> 1345
C28: Published | J28: Model | Q28: Model − published
C29: Brent \ crack | D29: 5 | E29: 10 | F29: 15 | G29: 20 | H29: 25 | J29: Brent \ crack | K29: =D29 -> 5 | L29: =E29 -> 10 | M29: =F29 -> 15 | N29: =G29 -> 20 | O29: =H29 -> 25 | Q29: Brent \ crack | R29: =D29 -> 5 | S29: =E29 -> 10 | T29: =F29 -> 15 | U29: =G29 -> 20 | V29: =H29 -> 25
C30: 126 | D30: 916 | E30: 920 | F30: 923 | G30: 928 | H30: 933 | J30: =C30 -> 126 | K30: =$C$24+$C$20*((Model!$C$5*(($C30)+Model!$C$6*(D$29)))-(Model!$C$5*(($C$22)+Model!$C$6*($C$23)))-$C$21*(((((Model!$C$5*(($C30)+Model!$C$6*(D$29)))-($C$25))*NORMSDIST(((Model!$C$5*(($C30)+Model!$C$6*(D$29)))-($C$25))/Model!$C$7)+Model!$C$7*EXP(-((((Model!$C$5*(($C30)+Model!$C$6*(D$29)))-($C$25))/Model!$C$7)^2)/2)/SQRT(2*PI()))-(((Model!$C$5*(($C30)+Model!$C$6*(D$29)))-($C$26))*NORMSDIST(((Model!$C$5*(($C30)+Model!$C$6*(D$29)))-($C$26))/Model!$C$7)+Model!$C$7*EXP(-((((Model!$C$5*(($C30)+Model!$C$6*(D$29)))-($C$26))/Model!$C$7)^2)/2)/SQRT(2*PI())))-((((Model!$C$5*(($C$22)+Model!$C$6*($C$23)))-($C$25))*NORMSDIST(((Model!$C$5*(($C$22)+Model!$C$6*($C$23)))-($C$25))/Model!$C$7)+Model!$C$7*EXP(-((((Model!$C$5*(($C$22)+Model!$C$6*($C$23)))-($C$25))/Model!$C$7)^2)/2)/SQRT(2*PI()))-(((Model!$C$5*(($C$22)+Model!$C$6*($C$23)))-($C$26))*NORMSDIST(((Model!$C$5*(($C$22)+Model!$C$6*($C$23)))-($C$26))/Model!$C$7)+Model!$C$7*EXP(-((((Model!$C$5*(($C$22)+Model!$C$6*($C$23)))-($C$26))/Model!$C$7)^2)/2)/SQRT(2*PI()))))) -> 919.1565 | L30: =$C$24+$C$20*((Model!$C$5*(($C30)+Model!$C$6*(E$29)))-(Model!$C$5*(($C$22)+Model!$C$6*($C$23)))-$C$21*(((((Model!$C$5*(($C30)+Model!$C$6*(E$29)))-($C$25))*NORMSDIST(((Model!$C$5*(($C30)+Model!$C$6*(E$29)))-($C$25))/Model!$C$7)+Model!$C$7*EXP(-((((Model!$C$5*(($C30)+Model!$C$6*(E$29)))-($C$25))/Model!$C$7)^2)/2)/SQRT(2*PI()))-(((Model!$C$5*(($C30)+Model!$C$6*(E$29)))-($C$26))*NORMSDIST(((Model!$C$5*(($C30)+Model!$C$6*(E$29)))-($C$26))/Model!$C$7)+Model!$C$7*EXP(-((((Model!$C$5*(($C30)+Model!$C$6*(E$29)))-($C$26))/Model!$C$7)^2)/2)/SQRT(2*PI())))-((((Model!$C$5*(($C$22)+Model!$C$6*($C$23)))-($C$25))*NORMSDIST(((Model!$C$5*(($C$22)+Model!$C$6*($C$23)))-($C$25))/Model!$C$7)+Model!$C$7*EXP(-((((Model!$C$5*(($C$22)+Model!$C$6*($C$23)))-($C$25))/Model!$C$7)^2)/2)/SQRT(2*PI()))-(((Model!$C$5*(($C$22)+Model!$C$6*($C$23)))-($C$26))*NORMSDIST(((Model!$C$5*(($C$22)+Model!$C$6*($C$23)))-($C$26))/Model!$C$7)+Model!$C$7*EXP(-((((Model!$C$5*(($C$22)+Model!$C$6*($C$23)))-($C$26))/Model!$C$7)^2)/2)/SQRT(2*PI()))))) -> 921.98477 | M30: =$C$24+$C$20*((Model!$C$5*(($C30)+Model!$C$6*(F$29)))-(Model!$C$5*(($C$22)+Model!$C$6*($C$23)))-$C$21*(((((Model!$C$5*(($C30)+Model!$C$6*(F$29)))-($C$25))*NORMSDIST(((Model!$C$5*(($C30)+Model!$C$6*(F$29)))-($C$25))/Model!$C$7)+Model!$C$7*EXP(-((((Model!$C$5*(($C30)+Model!$C$6*(F$29)))-($C$25))/Model!$C$7)^2)/2)/SQRT(2*PI()))-(((Model!$C$5*(($C30)+Model!$C$6*(F$29)))-($C$26))*NORMSDIST(((Model!$C$5*(($C30)+Model!$C$6*(F$29)))-($C$26))/Model!$C$7)+Model!$C$7*EXP(-((((Model!$C$5*(($C30)+Model!$C$6*(F$29)))-($C$26))/Model!$C$7)^2)/2)/SQRT(2*PI())))-((((Model!$C$5*(($C$22)+Model!$C$6*($C$23)))-($C$25))*NORMSDIST(((Model!$C$5*(($C$22)+Model!$C$6*($C$23)))-($C$25))/Model!$C$7)+Model!$C$7*EXP(-((((Model!$C$5*(($C$22)+Model!$C$6*($C$23)))-($C$25))/Model!$C$7)^2)/2)/SQRT(2*PI()))-(((Model!$C$5*(($C$22)+Model!$C$6*($C$23)))-($C$26))*NORMSDIST(((Model!$C$5*(($C$22)+Model!$C$6*($C$23)))-($C$26))/Model!$C$7)+Model!$C$7*EXP(-((((Model!$C$5*(($C$22)+Model!$C$6*($C$23)))-($C$26))/Model!$C$7)^2)/2)/SQRT(2*PI()))))) -> 924.66026 | N30: =$C$24+$C$20*((Model!$C$5*(($C30)+Model!$C$6*(G$29)))-(Model!$C$5*(($C$22)+Model!$C$6*($C$23)))-$C$21*(((((Model!$C$5*(($C30)+Model!$C$6*(G$29)))-($C$25))*NORMSDIST(((Model!$C$5*(($C30)+Model!$C$6*(G$29)))-($C$25))/Model!$C$7)+Model!$C$7*EXP(-((((Model!$C$5*(($C30)+Model!$C$6*(G$29)))-($C$25))/Model!$C$7)^2)/2)/SQRT(2*PI()))-(((Model!$C$5*(($C30)+Model!$C$6*(G$29)))-($C$26))*NORMSDIST(((Model!$C$5*(($C30)+Model!$C$6*(G$29)))-($C$26))/Model!$C$7)+Model!$C$7*EXP(-((((Model!$C$5*(($C30)+Model!$C$6*(G$29)))-($C$26))/Model!$C$7)^2)/2)/SQRT(2*PI())))-((((Model!$C$5*(($C$22)+Model!$C$6*($C$23)))-($C$25))*NORMSDIST(((Model!$C$5*(($C$22)+Model!$C$6*($C$23)))-($C$25))/Model!$C$7)+Model!$C$7*EXP(-((((Model!$C$5*(($C$22)+Model!$C$6*($C$23)))-($C$25))/Model!$C$7)^2)/2)/SQRT(2*PI()))-(((Model!$C$5*(($C$22)+Model!$C$6*($C$23)))-($C$26))*NORMSDIST(((Model!$C$5*(($C$22)+Model!$C$6*($C$23)))-($C$26))/Model!$C$7)+Model!$C$7*EXP(-((((Model!$C$5*(($C$22)+Model!$C$6*($C$23)))-($C$26))/Model!$C$7)^2)/2)/SQRT(2*PI()))))) -> 927.36074 | O30: =$C$24+$C$20*((Model!$C$5*(($C30)+Model!$C$6*(H$29)))-(Model!$C$5*(($C$22)+Model!$C$6*($C$23)))-$C$21*(((((Model!$C$5*(($C30)+Model!$C$6*(H$29)))-($C$25))*NORMSDIST(((Model!$C$5*(($C30)+Model!$C$6*(H$29)))-($C$25))/Model!$C$7)+Model!$C$7*EXP(-((((Model!$C$5*(($C30)+Model!$C$6*(H$29)))-($C$25))/Model!$C$7)^2)/2)/SQRT(2*PI()))-(((Model!$C$5*(($C30)+Model!$C$6*(H$29)))-($C$26))*NORMSDIST(((Model!$C$5*(($C30)+Model!$C$6*(H$29)))-($C$26))/Model!$C$7)+Model!$C$7*EXP(-((((Model!$C$5*(($C30)+Model!$C$6*(H$29)))-($C$26))/Model!$C$7)^2)/2)/SQRT(2*PI())))-((((Model!$C$5*(($C$22)+Model!$C$6*($C$23)))-($C$25))*NORMSDIST(((Model!$C$5*(($C$22)+Model!$C$6*($C$23)))-($C$25))/Model!$C$7)+Model!$C$7*EXP(-((((Model!$C$5*(($C$22)+Model!$C$6*($C$23)))-($C$25))/Model!$C$7)^2)/2)/SQRT(2*PI()))-(((Model!$C$5*(($C$22)+Model!$C$6*($C$23)))-($C$26))*NORMSDIST(((Model!$C$5*(($C$22)+Model!$C$6*($C$23)))-($C$26))/Model!$C$7)+Model!$C$7*EXP(-((((Model!$C$5*(($C$22)+Model!$C$6*($C$23)))-($C$26))/Model!$C$7)^2)/2)/SQRT(2*PI()))))) -> 930.2617 | Q30: =C30 -> 126 | R30: =K30-D30 -> 3.156498 | S30: =L30-E30 -> 1.9847698 | T30: =M30-F30 -> 1.6602565 | U30: =N30-G30 -> -0.63925738 | V30: =O30-H30 -> -2.7383016
